Workbook

Sheet Kitoblar Katalogi
A1: 📚 KITOBLAR KATALOGI — Boshqaruv Tizimi
A2: ID | B2: Kitob nomi | C2: Muallif | D2: Janr | E2: Narx (so'm) | F2: Soni | G2: Umumiy qiymat
A3: 1 | B3: O'tkan kunlar | C3: Abdulla Qodiriy | D3: Fantastika | E3: 98810 | F3: 8 | G3: =E3*F3 -> 790480
A4: 2 | B4: Mehrobdan chayon | C4: Abdulla Qodiriy | D4: Tarix | E4: 18278 | F4: 48 | G4: =E4*F4 -> 877344
A5: 3 | B5: Sarob | C5: Abdulla Qahhor | D5: Ilm-fan | E5: 51048 | F5: 16 | G5: =E5*F5 -> 816768
A6: 4 | B6: Qo'shchinor chiroqlari | C6: Oybek | D6: She'riyat | E6: 44256 | F6: 9 | G6: =E6*F6 -> 398304
A7: 5 | B7: Navoiy | C7: Oybek | D7: Falsafa | E7: 111530 | F7: 7 | G7: =E7*F7 -> 780710
A8: 6 | B8: Ulug'bek xazinasi | C8: Mirmuhsin | D8: Biografiya | E8: 103696 | F8: 48 | G8: =E8*F8 -> 4977408
A9: 7 | B9: Shum bola | C9: G'afur G'ulom | D9: Detektiv | E9: 86482 | F9: 6 | G9: =E9*F9 -> 518892
A10: 8 | B10: Dunyoning ishlari | C10: Said Ahmad | D10: Psixologiya | E10: 92397 | F10: 28 | G10: =E10*F10 -> 2587116
A11: 9 | B11: Yulduzli tunlar | C11: Pirimqul Qodirov | D11: Bolalar | E11: 19165 | F11: 2 | G11: =E11*F11 -> 38330
A12: 10 | B12: Avlodlar dovoni | C12: Pirimqul Qodirov | D12: Roman | E12: 27280 | F12: 14 | G12: =E12*F12 -> 381920
A13: 11 | B13: Don Kixot | C13: Servantes | D13: Fantastika | E13: 45495 | F13: 33 | G13: =E13*F13 -> 1501335
A14: 12 | B14: Romeo va Juletta | C14: Shekspir | D14: Tarix | E14: 93907 | F14: 2 | G14: =E14*F14 -> 187814
... A52: 50 | B52: Ko'hna dunyo | C52: Tog'ay Murod | D52: Roman | E52: 47087 | F52: 11 | G52: =E52*F52 -> 517957
A53: JAMI: | F53: =SUM(F3:F52) -> 1174 | G53: =SUM(G3:G52) -> 75901020

Sheet ID bo'yicha Qidiruv
A1: 🔍 ID bo'yicha Kitob Qidirish
A3: Kitob ID kiriting: | B3: 1
A5: ID | B5: Kitob nomi | C5: Muallif | D5: Janr | E5: Narx (so'm) | F5: Soni | G5: Umumiy qiymat
A6: =IFERROR(VLOOKUP(B3,'Kitoblar Katalogi'!A:G,1,FALSE()),"Topilmadi") -> 1 | B6: =IFERROR(VLOOKUP(B3,'Kitoblar Katalogi'!A:G,2,FALSE()),"") -> O'tkan kunlar | C6: =IFERROR(VLOOKUP(B3,'Kitoblar Katalogi'!A:G,3,FALSE()),"") -> Abdulla Qodiriy | D6: =IFERROR(VLOOKUP(B3,'Kitoblar Katalogi'!A:G,4,FALSE()),"") -> Fantastika | E6: =IFERROR(VLOOKUP(B3,'Kitoblar Katalogi'!A:G,5,FALSE()),"") -> 98810 | F6: =IFERROR(VLOOKUP(B3,'Kitoblar Katalogi'!A:G,6,FALSE()),"") -> 8 | G6: =IFERROR(VLOOKUP(B3,'Kitoblar Katalogi'!A:G,7,FALSE()),"") -> 790480
A8: 💡 B3 katakdagi ID raqamini o'zgartiring — natija avtomatik yangilanadi.

Sheet Narx bo'yicha Saralash
A1: 💰 Narx bo'yicha Saralangan Kitoblar
A2: ID | B2: Kitob nomi | C2: Muallif | D2: Janr | E2: Narx (so'm) | F2: Soni | G2: Umumiy qiymat
A3: =IFERROR(INDEX('Kitoblar Katalogi'!A$3:A$52,MATCH(LARGE('Kitoblar Katalogi'!E$3:E$52,1),'Kitoblar Katalogi'!E$3:E$52,0)),"") -> 23 | B3: =IFERROR(INDEX('Kitoblar Katalogi'!B$3:B$52,MATCH(LARGE('Kitoblar Katalogi'!E$3:E$52,1),'Kitoblar Katalogi'!E$3:E$52,0)),"") -> Buyuk Getsbi | C3: =IFERROR(INDEX('Kitoblar Katalogi'!C$3:C$52,MATCH(LARGE('Kitoblar Katalogi'!E$3:E$52,1),'Kitoblar Katalogi'!E$3:E$52,0)),"") -> Fitzgerald | D3: =IFERROR(INDEX('Kitoblar Katalogi'!D$3:D$52,MATCH(LARGE('Kitoblar Katalogi'!E$3:E$52,1),'Kitoblar Katalogi'!E$3:E$52,0)),"") -> Ilm-fan | E3: =IFERROR(LARGE('Kitoblar Katalogi'!E$3:E$52,1),"") -> 115072 | F3: =IFERROR(INDEX('Kitoblar Katalogi'!F$3:F$52,MATCH(LARGE('Kitoblar Katalogi'!E$3:E$52,1),'Kitoblar Katalogi'!E$3:E$52,0)),"") -> 22 | G3: =IFERROR(INDEX('Kitoblar Katalogi'!G$3:G$52,MATCH(LARGE('Kitoblar Katalogi'!E$3:E$52,1),'Kitoblar Katalogi'!E$3:E$52,0)),"") -> 2531584
A4: =IFERROR(INDEX('Kitoblar Katalogi'!A$3:A$52,MATCH(LARGE('Kitoblar Katalogi'!E$3:E$52,2),'Kitoblar Katalogi'!E$3:E$52,0)),"") -> 19 | B4: =IFERROR(INDEX('Kitoblar Katalogi'!B$3:B$52,MATCH(LARGE('Kitoblar Katalogi'!E$3:E$52,2),'Kitoblar Katalogi'!E$3:E$52,0)),"") -> Alximik | C4: =IFERROR(INDEX('Kitoblar Katalogi'!C$3:C$52,MATCH(LARGE('Kitoblar Katalogi'!E$3:E$52,2),'Kitoblar Katalogi'!E$3:E$52,0)),"") -> Koelo | D4: =IFERROR(INDEX('Kitoblar Katalogi'!D$3:D$52,MATCH(LARGE('Kitoblar Katalogi'!E$3:E$52,2),'Kitoblar Katalogi'!E$3:E$52,0)),"") -> Bolalar | E4: =IFERROR(LARGE('Kitoblar Katalogi'!E$3:E$52,2),"") -> 114458 | F4: =IFERROR(INDEX('Kitoblar Katalogi'!F$3:F$52,MATCH(LARGE('Kitoblar Katalogi'!E$3:E$52,2),'Kitoblar Katalogi'!E$3:E$52,0)),"") -> 11 | G4: =IFERROR(INDEX('Kitoblar Katalogi'!G$3:G$52,MATCH(LARGE('Kitoblar Katalogi'!E$3:E$52,2),'Kitoblar Katalogi'!E$3:E$52,0)),"") -> 1259038
A5: =IFERROR(INDEX('Kitoblar Katalogi'!A$3:A$52,MATCH(LARGE('Kitoblar Katalogi'!E$3:E$52,3),'Kitoblar Katalogi'!E$3:E$52,0)),"") -> 5 | B5: =IFERROR(INDEX('Kitoblar Katalogi'!B$3:B$52,MATCH(LARGE('Kitoblar Katalogi'!E$3:E$52,3),'Kitoblar Katalogi'!E$3:E$52,0)),"") -> Navoiy | C5: =IFERROR(INDEX('Kitoblar Katalogi'!C$3:C$52,MATCH(LARGE('Kitoblar Katalogi'!E$3:E$52,3),'Kitoblar Katalogi'!E$3:E$52,0)),"") -> Oybek | D5: =IFERROR(INDEX('Kitoblar Katalogi'!D$3:D$52,MATCH(LARGE('Kitoblar Katalogi'!E$3:E$52,3),'Kitoblar Katalogi'!E$3:E$52,0)),"") -> Falsafa | E5: =IFERROR(LARGE('Kitoblar Katalogi'!E$3:E$52,3),"") -> 111530 | F5: =IFERROR(INDEX('Kitoblar Katalogi'!F$3:F$52,MATCH(LARGE('Kitoblar Katalogi'!E$3:E$52,3),'Kitoblar Katalogi'!E$3:E$52,0)),"") -> 7 | G5: =IFERROR(INDEX('Kitoblar Katalogi'!G$3:G$52,MATCH(LARGE('Kitoblar Katalogi'!E$3:E$52,3),'Kitoblar Katalogi'!E$3:E$52,0)),"") -> 780710
A6: =IFERROR(INDEX('Kitoblar Katalogi'!A$3:A$52,MATCH(LARGE('Kitoblar Katalogi'!E$3:E$52,4),'Kitoblar Katalogi'!E$3:E$52,0)),"") -> 14 | B6: =IFERROR(INDEX('Kitoblar Katalogi'!B$3:B$52,MATCH(LARGE('Kitoblar Katalogi'!E$3:E$52,4),'Kitoblar Katalogi'!E$3:E$52,0)),"") -> Anna Karenina | C6: =IFERROR(INDEX('Kitoblar Katalogi'!C$3:C$52,MATCH(LARGE('Kitoblar Katalogi'!E$3:E$52,4),'Kitoblar Katalogi'!E$3:E$52,0)),"") -> Tolstoy | D6: =IFERROR(INDEX('Kitoblar Katalogi'!D$3:D$52,MATCH(LARGE('Kitoblar Katalogi'!E$3:E$52,4),'Kitoblar Katalogi'!E$3:E$52,0)),"") -> She'riyat | E6: =IFERROR(LARGE('Kitoblar Katalogi'!E$3:E$52,4),"") -> 108850 | F6: =IFERROR(INDEX('Kitoblar Katalogi'!F$3:F$52,MATCH(LARGE('Kitoblar Katalogi'!E$3:E$52,4),'Kitoblar Katalogi'!E$3:E$52,0)),"") -> 42 | G6: =IFERROR(INDEX('Kitoblar Katalogi'!G$3:G$52,MATCH(LARGE('Kitoblar Katalogi'!E$3:E$52,4),'Kitoblar Katalogi'!E$3:E$52,0)),"") -> 4571700
A7: =IFERROR(INDEX('Kitoblar Katalogi'!A$3:A$52,MATCH(LARGE('Kitoblar Katalogi'!E$3:E$52,5),'Kitoblar Katalogi'!E$3:E$52,0)),"") -> 35 | B7: =IFERROR(INDEX('Kitoblar Katalogi'!B$3:B$52,MATCH(LARGE('Kitoblar Katalogi'!E$3:E$52,5),'Kitoblar Katalogi'!E$3:E$52,0)),"") -> Makbet | C7: =IFERROR(INDEX('Kitoblar Katalogi'!C$3:C$52,MATCH(LARGE('Kitoblar Katalogi'!E$3:E$52,5),'Kitoblar Katalogi'!E$3:E$52,0)),"") -> Shekspir | D7: =IFERROR(INDEX('Kitoblar Katalogi'!D$3:D$52,MATCH(LARGE('Kitoblar Katalogi'!E$3:E$52,5),'Kitoblar Katalogi'!E$3:E$52,0)),"") -> Falsafa | E7: =IFERROR(LARGE('Kitoblar Katalogi'!E$3:E$52,5),"") -> 107349 | F7: =IFERROR(INDEX('Kitoblar Katalogi'!F$3:F$52,MATCH(LARGE('Kitoblar Katalogi'!E$3:E$52,5),'Kitoblar Katalogi'!E$3:E$52,0)),"") -> 5 | G7: =IFERROR(INDEX('Kitoblar Katalogi'!G$3:G$52,MATCH(LARGE('Kitoblar Katalogi'!E$3:E$52,5),'Kitoblar Katalogi'!E$3:E$52,0)),"") -> 536745
A8: =IFERROR(INDEX('Kitoblar Katalogi'!A$3:A$52,MATCH(LARGE('Kitoblar Katalogi'!E$3:E$52,6),'Kitoblar Katalogi'!E$3:E$52,0)),"") -> 15 | B8: =IFERROR(INDEX('Kitoblar Katalogi'!B$3:B$52,MATCH(LARGE('Kitoblar Katalogi'!E$3:E$52,6),'Kitoblar Katalogi'!E$3:E$52,0)),"") -> Jinoyat va jazo | C8: =IFERROR(INDEX('Kitoblar Katalogi'!C$3:C$52,MATCH(LARGE('Kitoblar Katalogi'!E$3:E$52,6),'Kitoblar Katalogi'!E$3:E$52,0)),"") -> Dostoevskiy | D8: =IFERROR(INDEX('Kitoblar Katalogi'!D$3:D$52,MATCH(LARGE('Kitoblar Katalogi'!E$3:E$52,6),'Kitoblar Katalogi'!E$3:E$52,0)),"") -> Falsafa | E8: =IFERROR(LARGE('Kitoblar Katalogi'!E$3:E$52,6),"") -> 106924 | F8: =IFERROR(INDEX('Kitoblar Katalogi'!F$3:F$52,MATCH(LARGE('Kitoblar Katalogi'!E$3:E$52,6),'Kitoblar Katalogi'!E$3:E$52,0)),"") -> 35 | G8: =IFERROR(INDEX('Kitoblar Katalogi'!G$3:G$52,MATCH(LARGE('Kitoblar Katalogi'!E$3:E$52,6),'Kitoblar Katalogi'!E$3:E$52,0)),"") -> 3742340
A9: =IFERROR(INDEX('Kitoblar Katalogi'!A$3:A$52,MATCH(LARGE('Kitoblar Katalogi'!E$3:E$52,7),'Kitoblar Katalogi'!E$3:E$52,0)),"") -> 20 | B9: =IFERROR(INDEX('Kitoblar Katalogi'!B$3:B$52,MATCH(LARGE('Kitoblar Katalogi'!E$3:E$52,7),'Kitoblar Katalogi'!E$3:E$52,0)),"") -> Pinhon hayot | C9: =IFERROR(INDEX('Kitoblar Katalogi'!C$3:C$52,MATCH(LARGE('Kitoblar Katalogi'!E$3:E$52,7),'Kitoblar Katalogi'!E$3:E$52,0)),"") -> Orhan Pamuk | D9: =IFERROR(INDEX('Kitoblar Katalogi'!D$3:D$52,MATCH(LARGE('Kitoblar Katalogi'!E$3:E$52,7),'Kitoblar Katalogi'!E$3:E$52,0)),"") -> Roman | E9: =IFERROR(LARGE('Kitoblar Katalogi'!E$3:E$52,7),"") -> 106506 | F9: =IFERROR(INDEX('Kitoblar Katalogi'!F$3:F$52,MATCH(LARGE('Kitoblar Katalogi'!E$3:E$52,7),'Kitoblar Katalogi'!E$3:E$52,0)),"") -> 28 | G9: =IFERROR(INDEX('Kitoblar Katalogi'!G$3:G$52,MATCH(LARGE('Kitoblar Katalogi'!E$3:E$52,7),'Kitoblar Katalogi'!E$3:E$52,0)),"") -> 2982168
A10: =IFERROR(INDEX('Kitoblar Katalogi'!A$3:A$52,MATCH(LARGE('Kitoblar Katalogi'!E$3:E$52,8),'Kitoblar Katalogi'!E$3:E$52,0)),"") -> 46 | B10: =IFERROR(INDEX('Kitoblar Katalogi'!B$3:B$52,MATCH(LARGE('Kitoblar Katalogi'!E$3:E$52,8),'Kitoblar Katalogi'!E$3:E$52,0)),"") -> Alisa mo'jizalar mamlakatida | C10: =IFERROR(INDEX('Kitoblar Katalogi'!C$3:C$52,MATCH(LARGE('Kitoblar Katalogi'!E$3:E$52,8),'Kitoblar Katalogi'!E$3:E$52,0)),"") -> Kerroll | D10: =IFERROR(INDEX('Kitoblar Katalogi'!D$3:D$52,MATCH(LARGE('Kitoblar Katalogi'!E$3:E$52,8),'Kitoblar Katalogi'!E$3:E$52,0)),"") -> Biografiya | E10: =IFERROR(LARGE('Kitoblar Katalogi'!E$3:E$52,8),"") -> 104593 | F10: =IFERROR(INDEX('Kitoblar Katalogi'!F$3:F$52,MATCH(LARGE('Kitoblar Katalogi'!E$3:E$52,8),'Kitoblar Katalogi'!E$3:E$52,0)),"") -> 42 | G10: =IFERROR(INDEX('Kitoblar Katalogi'!G$3:G$52,MATCH(LARGE('Kitoblar Katalogi'!E$3:E$52,8),'Kitoblar Katalogi'!E$3:E$52,0)),"") -> 4392906
A11: =IFERROR(INDEX('Kitoblar Katalogi'!A$3:A$52,MATCH(LARGE('Kitoblar Katalogi'!E$3:E$52,9),'Kitoblar Katalogi'!E$3:E$52,0)),"") -> 6 | B11: =IFERROR(INDEX('Kitoblar Katalogi'!B$3:B$52,MATCH(LARGE('Kitoblar Katalogi'!E$3:E$52,9),'Kitoblar Katalogi'!E$3:E$52,0)),"") -> Ulug'bek xazinasi | C11: =IFERROR(INDEX('Kitoblar Katalogi'!C$3:C$52,MATCH(LARGE('Kitoblar Katalogi'!E$3:E$52,9),'Kitoblar Katalogi'!E$3:E$52,0)),"") -> Mirmuhsin | D11: =IFERROR(INDEX('Kitoblar Katalogi'!D$3:D$52,MATCH(LARGE('Kitoblar Katalogi'!E$3:E$52,9),'Kitoblar Katalogi'!E$3:E$52,0)),"") -> Biografiya | E11: =IFERROR(LARGE('Kitoblar Katalogi'!E$3:E$52,9),"") -> 103696 | F11: =IFERROR(INDEX('Kitoblar Katalogi'!F$3:F$52,MATCH(LARGE('Kitoblar Katalogi'!E$3:E$52,9),'Kitoblar Katalogi'!E$3:E$52,0)),"") -> 48 | G11: =IFERROR(INDEX('Kitoblar Katalogi'!G$3:G$52,MATCH(LARGE('Kitoblar Katalogi'!E$3:E$52,9),'Kitoblar Katalogi'!E$3:E$52,0)),"") -> 4977408
A12: =IFERROR(INDEX('Kitoblar Katalogi'!A$3:A$52,MATCH(LARGE('Kitoblar Katalogi'!E$3:E$52,10),'Kitoblar Katalogi'!E$3:E$52,0)),"") -> 1 | B12: =IFERROR(INDEX('Kitoblar Katalogi'!B$3:B$52,MATCH(LARGE('Kitoblar Katalogi'!E$3:E$52,10),'Kitoblar Katalogi'!E$3:E$52,0)),"") -> O'tkan kunlar | C12: =IFERROR(INDEX('Kitoblar Katalogi'!C$3:C$52,MATCH(LARGE('Kitoblar Katalogi'!E$3:E$52,10),'Kitoblar Katalogi'!E$3:E$52,0)),"") -> Abdulla Qodiriy | D12: =IFERROR(INDEX('Kitoblar Katalogi'!D$3:D$52,MATCH(LARGE('Kitoblar Katalogi'!E$3:E$52,10),'Kitoblar Katalogi'!E$3:E$52,0)),"") -> Fantastika | E12: =IFERROR(LARGE('Kitoblar Katalogi'!E$3:E$52,10),"") -> 98810 | F12: =IFERROR(INDEX('Kitoblar Katalogi'!F$3:F$52,MATCH(LARGE('Kitoblar Katalogi'!E$3:E$52,10),'Kitoblar Katalogi'!E$3:E$52,0)),"") -> 8 | G12: =IFERROR(INDEX('Kitoblar Katalogi'!G$3:G$52,MATCH(LARGE('Kitoblar Katalogi'!E$3:E$52,10),'Kitoblar Katalogi'!E$3:E$52,0)),"") -> 790480
A13: =IFERROR(INDEX('Kitoblar Katalogi'!A$3:A$52,MATCH(LARGE('Kitoblar Katalogi'!E$3:E$52,11),'Kitoblar Katalogi'!E$3:E$52,0)),"") -> 48 | B13: =IFERROR(INDEX('Kitoblar Katalogi'!B$3:B$52,MATCH(LARGE('Kitoblar Katalogi'!E$3:E$52,11),'Kitoblar Katalogi'!E$3:E$52,0)),"") -> Sincaloy | C13: =IFERROR(INDEX('Kitoblar Katalogi'!C$3:C$52,MATCH(LARGE('Kitoblar Katalogi'!E$3:E$52,11),'Kitoblar Katalogi'!E$3:E$52,0)),"") -> Asqad Muxtor | D13: =IFERROR(INDEX('Kitoblar Katalogi'!D$3:D$52,MATCH(LARGE('Kitoblar Katalogi'!E$3:E$52,11),'Kitoblar Katalogi'!E$3:E$52,0)),"") -> Psixologiya | E13: =IFERROR(LARGE('Kitoblar Katalogi'!E$3:E$52,11),"") -> 98227 | F13: =IFERROR(INDEX('Kitoblar Katalogi'!F$3:F$52,MATCH(LARGE('Kitoblar Katalogi'!E$3:E$52,11),'Kitoblar Katalogi'!E$3:E$52,0)),"") -> 11 | G13: =IFERROR(INDEX('Kitoblar Katalogi'!G$3:G$52,MATCH(LARGE('Kitoblar Katalogi'!E$3:E$52,11),'Kitoblar Katalogi'!E$3:E$52,0)),"") -> 1080497
A14: =IFERROR(INDEX('Kitoblar Katalogi'!A$3:A$52,MATCH(LARGE('Kitoblar Katalogi'!E$3:E$52,12),'Kitoblar Katalogi'!E$3:E$52,0)),"") -> 33 | B14: =IFERROR(INDEX('Kitoblar Katalogi'!B$3:B$52,MATCH(LARGE('Kitoblar Katalogi'!E$3:E$52,12),'Kitoblar Katalogi'!E$3:E$52,0)),"") -> Dante Aligeri | C14: =IFERROR(INDEX('Kitoblar Katalogi'!C$3:C$52,MATCH(LARGE('Kitoblar Katalogi'!E$3:E$52,12),'Kitoblar Katalogi'!E$3:E$52,0)),"") -> Ilohiy komediya | D14: =IFERROR(INDEX('Kitoblar Katalogi'!D$3:D$52,MATCH(LARGE('Kitoblar Katalogi'!E$3:E$52,12),'Kitoblar Katalogi'!E$3:E$52,0)),"") -> Ilm-fan | E14: =IFERROR(LARGE('Kitoblar Katalogi'!E$3:E$52,12),"") -> 96070 | F14: =IFERROR(INDEX('Kitoblar Katalogi'!F$3:F$52,MATCH(LARGE('Kitoblar Katalogi'!E$3:E$52,12),'Kitoblar Katalogi'!E$3:E$52,0)),"") -> 24 | G14: =IFERROR(INDEX('Kitoblar Katalogi'!G$3:G$52,MATCH(LARGE('Kitoblar Katalogi'!E$3:E$52,12),'Kitoblar Katalogi'!E$3:E$52,0)),"") -> 2305680
A15: =IFERROR(INDEX('Kitoblar Katalogi'!A$3:A$52,MATCH(LARGE('Kitoblar Katalogi'!E$3:E$52,13),'Kitoblar Katalogi'!E$3:E$52,0)),"") -> 27 | B15: =IFERROR(INDEX('Kitoblar Katalogi'!B$3:B$52,MATCH(LARGE('Kitoblar Katalogi'!E$3:E$52,13),'Kitoblar Katalogi'!E$3:E$52,0)),"") -> Yangi jasur dunyo | C15: =IFERROR(INDEX('Kitoblar Katalogi'!C$3:C$52,MATCH(LARGE('Kitoblar Katalogi'!E$3:E$52,13),'Kitoblar Katalogi'!E$3:E$52,0)),"") -> Oldos Haksli | D15: =IFERROR(INDEX('Kitoblar Katalogi'!D$3:D$52,MATCH(LARGE('Kitoblar Katalogi'!E$3:E$52,13),'Kitoblar Katalogi'!E$3:E$52,0)),"") -> Detektiv | E15: =IFERROR(LARGE('Kitoblar Katalogi'!E$3:E$52,13),"") -> 94131 | F15: =IFERROR(INDEX('Kitoblar Katalogi'!F$3:F$52,MATCH(LARGE('Kitoblar Katalogi'!E$3:E$52,13),'Kitoblar Katalogi'!E$3:E$52,0)),"") -> 17 | G15: =IFERROR(INDEX('Kitoblar Katalogi'!G$3:G$52,MATCH(LARGE('Kitoblar Katalogi'!E$3:E$52,13),'Kitoblar Katalogi'!E$3:E$52,0)),"") -> 1600227
A16: =IFERROR(INDEX('Kitoblar Katalogi'!A$3:A$52,MATCH(LARGE('Kitoblar Katalogi'!E$3:E$52,14),'Kitoblar Katalogi'!E$3:E$52,0)),"") -> 12 | B16: =IFERROR(INDEX('Kitoblar Katalogi'!B$3:B$52,MATCH(LARGE('Kitoblar Katalogi'!E$3:E$52,14),'Kitoblar Katalogi'!E$3:E$52,0)),"") -> Romeo va Juletta | C16: =IFERROR(INDEX('Kitoblar Katalogi'!C$3:C$52,MATCH(LARGE('Kitoblar Katalogi'!E$3:E$52,14),'Kitoblar Katalogi'!E$3:E$52,0)),"") -> Shekspir | D16: =IFERROR(INDEX('Kitoblar Katalogi'!D$3:D$52,MATCH(LARGE('Kitoblar Katalogi'!E$3:E$52,14),'Kitoblar Katalogi'!E$3:E$52,0)),"") -> Tarix | E16: =IFERROR(LARGE('Kitoblar Katalogi'!E$3:E$52,14),"") -> 93907 | F16: =IFERROR(INDEX('Kitoblar Katalogi'!F$3:F$52,MATCH(LARGE('Kitoblar Katalogi'!E$3:E$52,14),'Kitoblar Katalogi'!E$3:E$52,0)),"") -> 2 | G16: =IFERROR(INDEX('Kitoblar Katalogi'!G$3:G$52,MATCH(LARGE('Kitoblar Katalogi'!E$3:E$52,14),'Kitoblar Katalogi'!E$3:E$52,0)),"") -> 187814
A17: =IFERROR(INDEX('Kitoblar Katalogi'!A$3:A$52,MATCH(LARGE('Kitoblar Katalogi'!E$3:E$52,15),'Kitoblar Katalogi'!E$3:E$52,0)),"") -> 8 | B17: =IFERROR(INDEX('Kitoblar Katalogi'!B$3:B$52,MATCH(LARGE('Kitoblar Katalogi'!E$3:E$52,15),'Kitoblar Katalogi'!E$3:E$52,0)),"") -> Dunyoning ishlari | C17: =IFERROR(INDEX('Kitoblar Katalogi'!C$3:C$52,MATCH(LARGE('Kitoblar Katalogi'!E$3:E$52,15),'Kitoblar Katalogi'!E$3:E$52,0)),"") -> Said Ahmad | D17: =IFERROR(INDEX('Kitoblar Katalogi'!D$3:D$52,MATCH(LARGE('Kitoblar Katalogi'!E$3:E$52,15),'Kitoblar Katalogi'!E$3:E$52,0)),"") -> Psixologiya | E17: =IFERROR(LARGE('Kitoblar Katalogi'!E$3:E$52,15),"") -> 92397 | F17: =IFERROR(INDEX('Kitoblar Katalogi'!F$3:F$52,MATCH(LARGE('Kitoblar Katalogi'!E$3:E$52,15),'Kitoblar Katalogi'!E$3:E$52,0)),"") -> 28 | G17: =IFERROR(INDEX('Kitoblar Katalogi'!G$3:G$52,MATCH(LARGE('Kitoblar Katalogi'!E$3:E$52,15),'Kitoblar Katalogi'!E$3:E$52,0)),"") -> 2587116
A18: =IFERROR(INDEX('Kitoblar Katalogi'!A$3:A$52,MATCH(LARGE('Kitoblar Katalogi'!E$3:E$52,16),'Kitoblar Katalogi'!E$3:E$52,0)),"") -> 34 | B18: =IFERROR(INDEX('Kitoblar Katalogi'!B$3:B$52,MATCH(LARGE('Kitoblar Katalogi'!E$3:E$52,16),'Kitoblar Katalogi'!E$3:E$52,0)),"") -> Hamlet | C18: =IFERROR(INDEX('Kitoblar Katalogi'!C$3:C$52,MATCH(LARGE('Kitoblar Katalogi'!E$3:E$52,16),'Kitoblar Katalogi'!E$3:E$52,0)),"") -> Shekspir | D18: =IFERROR(INDEX('Kitoblar Katalogi'!D$3:D$52,MATCH(LARGE('Kitoblar Katalogi'!E$3:E$52,16),'Kitoblar Katalogi'!E$3:E$52,0)),"") -> She'riyat | E18: =IFERROR(LARGE('Kitoblar Katalogi'!E$3:E$52,16),"") -> 90674 | F18: =IFERROR(INDEX('Kitoblar Katalogi'!F$3:F$52,MATCH(LARGE('Kitoblar Katalogi'!E$3:E$52,16),'Kitoblar Katalogi'!E$3:E$52,0)),"") -> 13 | G18: =IFERROR(INDEX('Kitoblar Katalogi'!G$3:G$52,MATCH(LARGE('Kitoblar Katalogi'!E$3:E$52,16),'Kitoblar Katalogi'!E$3:E$52,0)),"") -> 1178762
A19: =IFERROR(INDEX('Kitoblar Katalogi'!A$3:A$52,MATCH(LARGE('Kitoblar Katalogi'!E$3:E$52,17),'Kitoblar Katalogi'!E$3:E$52,0)),"") -> 13 | B19: =IFERROR(INDEX('Kitoblar Katalogi'!B$3:B$52,MATCH(LARGE('Kitoblar Katalogi'!E$3:E$52,17),'Kitoblar Katalogi'!E$3:E$52,0)),"") -> Urush va tinchlik | C19: =IFERROR(INDEX('Kitoblar Katalogi'!C$3:C$52,MATCH(LARGE('Kitoblar Katalogi'!E$3:E$52,17),'Kitoblar Katalogi'!E$3:E$52,0)),"") -> Tolstoy | D19: =IFERROR(INDEX('Kitoblar Katalogi'!D$3:D$52,MATCH(LARGE('Kitoblar Katalogi'!E$3:E$52,17),'Kitoblar Katalogi'!E$3:E$52,0)),"") -> Ilm-fan | E19: =IFERROR(LARGE('Kitoblar Katalogi'!E$3:E$52,17),"") -> 88563 | F19: =IFERROR(INDEX('Kitoblar Katalogi'!F$3:F$52,MATCH(LARGE('Kitoblar Katalogi'!E$3:E$52,17),'Kitoblar Katalogi'!E$3:E$52,0)),"") -> 13 | G19: =IFERROR(INDEX('Kitoblar Katalogi'!G$3:G$52,MATCH(LARGE('Kitoblar Katalogi'!E$3:E$52,17),'Kitoblar Katalogi'!E$3:E$52,0)),"") -> 1151319
A20: =IFERROR(INDEX('Kitoblar Katalogi'!A$3:A$52,MATCH(LARGE('Kitoblar Katalogi'!E$3:E$52,18),'Kitoblar Katalogi'!E$3:E$52,0)),"") -> 7 | B20: =IFERROR(INDEX('Kitoblar Katalogi'!B$3:B$52,MATCH(LARGE('Kitoblar Katalogi'!E$3:E$52,18),'Kitoblar Katalogi'!E$3:E$52,0)),"") -> Shum bola | C20: =IFERROR(INDEX('Kitoblar Katalogi'!C$3:C$52,MATCH(LARGE('Kitoblar Katalogi'!E$3:E$52,18),'Kitoblar Katalogi'!E$3:E$52,0)),"") -> G'afur G'ulom | D20: =IFERROR(INDEX('Kitoblar Katalogi'!D$3:D$52,MATCH(LARGE('Kitoblar Katalogi'!E$3:E$52,18),'Kitoblar Katalogi'!E$3:E$52,0)),"") -> Detektiv | E20: =IFERROR(LARGE('Kitoblar Katalogi'!E$3:E$52,18),"") -> 86482 | F20: =IFERROR(INDEX('Kitoblar Katalogi'!F$3:F$52,MATCH(LARGE('Kitoblar Katalogi'!E$3:E$52,18),'Kitoblar Katalogi'!E$3:E$52,0)),"") -> 6 | G20: =IFERROR(INDEX('Kitoblar Katalogi'!G$3:G$52,MATCH(LARGE('Kitoblar Katalogi'!E$3:E$52,18),'Kitoblar Katalogi'!E$3:E$52,0)),"") -> 518892
A21: =IFERROR(INDEX('Kitoblar Katalogi'!A$3:A$52,MATCH(LARGE('Kitoblar Katalogi'!E$3:E$52,19),'Kitoblar Katalogi'!E$3:E$52,0)),"") -> 49 | B21: =IFERROR(INDEX('Kitoblar Katalogi'!B$3:B$52,MATCH(LARGE('Kitoblar Katalogi'!E$3:E$52,19),'Kitoblar Katalogi'!E$3:E$52,0)),"") -> Dafina | C21: =IFERROR(INDEX('Kitoblar Katalogi'!C$3:C$52,MATCH(LARGE('Kitoblar Katalogi'!E$3:E$52,19),'Kitoblar Katalogi'!E$3:E$52,0)),"") -> Shukur Xolmirzayev | D21: =IFERROR(INDEX('Kitoblar Katalogi'!D$3:D$52,MATCH(LARGE('Kitoblar Katalogi'!E$3:E$52,19),'Kitoblar Katalogi'!E$3:E$52,0)),"") -> Bolalar | E21: =IFERROR(LARGE('Kitoblar Katalogi'!E$3:E$52,19),"") -> 85010 | F21: =IFERROR(INDEX('Kitoblar Katalogi'!F$3:F$52,MATCH(LARGE('Kitoblar Katalogi'!E$3:E$52,19),'Kitoblar Katalogi'!E$3:E$52,0)),"") -> 47 | G21: =IFERROR(INDEX('Kitoblar Katalogi'!G$3:G$52,MATCH(LARGE('Kitoblar Katalogi'!E$3:E$52,19),'Kitoblar Katalogi'!E$3:E$52,0)),"") -> 3995470
A22: =IFERROR(INDEX('Kitoblar Katalogi'!A$3:A$52,MATCH(LARGE('Kitoblar Katalogi'!E$3:E$52,20),'Kitoblar Katalogi'!E$3:E$52,0)),"") -> 29 | B22: =IFERROR(INDEX('Kitoblar Katalogi'!B$3:B$52,MATCH(LARGE('Kitoblar Katalogi'!E$3:E$52,20),'Kitoblar Katalogi'!E$3:E$52,0)),"") -> Yo'qolgan vaqt izidan | C22: =IFERROR(INDEX('Kitoblar Katalogi'!C$3:C$52,MATCH(LARGE('Kitoblar Katalogi'!E$3:E$52,20),'Kitoblar Katalogi'!E$3:E$52,0)),"") -> Prust | D22: =IFERROR(INDEX('Kitoblar Katalogi'!D$3:D$52,MATCH(LARGE('Kitoblar Katalogi'!E$3:E$52,20),'Kitoblar Katalogi'!E$3:E$52,0)),"") -> Bolalar | E22: =IFERROR(LARGE('Kitoblar Katalogi'!E$3:E$52,20),"") -> 75217 | F22: =IFERROR(INDEX('Kitoblar Katalogi'!F$3:F$52,MATCH(LARGE('Kitoblar Katalogi'!E$3:E$52,20),'Kitoblar Katalogi'!E$3:E$52,0)),"") -> 35 | G22: =IFERROR(INDEX('Kitoblar Katalogi'!G$3:G$52,MATCH(LARGE('Kitoblar Katalogi'!E$3:E$52,20),'Kitoblar Katalogi'!E$3:E$52,0)),"") -> 2632595
A23: =IFERROR(INDEX('Kitoblar Katalogi'!A$3:A$52,MATCH(LARGE('Kitoblar Katalogi'!E$3:E$52,21),'Kitoblar Katalogi'!E$3:E$52,0)),"") -> 41 | B23: =IFERROR(INDEX('Kitoblar Katalogi'!B$3:B$52,MATCH(LARGE('Kitoblar Katalogi'!E$3:E$52,21),'Kitoblar Katalogi'!E$3:E$52,0)),"") -> Qizil va qora | C23: =IFERROR(INDEX('Kitoblar Katalogi'!C$3:C$52,MATCH(LARGE('Kitoblar Katalogi'!E$3:E$52,21),'Kitoblar Katalogi'!E$3:E$52,0)),"") -> Stendal | D23: =IFERROR(INDEX('Kitoblar Katalogi'!D$3:D$52,MATCH(LARGE('Kitoblar Katalogi'!E$3:E$52,21),'Kitoblar Katalogi'!E$3:E$52,0)),"") -> Fantastika | E23: =IFERROR(LARGE('Kitoblar Katalogi'!E$3:E$52,21),"") -> 74429 | F23: =IFERROR(INDEX('Kitoblar Katalogi'!F$3:F$52,MATCH(LARGE('Kitoblar Katalogi'!E$3:E$52,21),'Kitoblar Katalogi'!E$3:E$52,0)),"") -> 41 | G23: =IFERROR(INDEX('Kitoblar Katalogi'!G$3:G$52,MATCH(LARGE('Kitoblar Katalogi'!E$3:E$52,21),'Kitoblar Katalogi'!E$3:E$52,0)),"") -> 3051589
A24: =IFERROR(INDEX('Kitoblar Katalogi'!A$3:A$52,MATCH(LARGE('Kitoblar Katalogi'!E$3:E$52,22),'Kitoblar Katalogi'!E$3:E$52,0)),"") -> 17 | B24: =IFERROR(INDEX('Kitoblar Katalogi'!B$3:B$52,MATCH(LARGE('Kitoblar Katalogi'!E$3:E$52,22),'Kitoblar Katalogi'!E$3:E$52,0)),"") -> Usta va Margarita | C24: =IFERROR(INDEX('Kitoblar Katalogi'!C$3:C$52,MATCH(LARGE('Kitoblar Katalogi'!E$3:E$52,22),'Kitoblar Katalogi'!E$3:E$52,0)),"") -> Bulgakov | D24: =IFERROR(INDEX('Kitoblar Katalogi'!D$3:D$52,MATCH(LARGE('Kitoblar Katalogi'!E$3:E$52,22),'Kitoblar Katalogi'!E$3:E$52,0)),"") -> Detektiv | E24: =IFERROR(LARGE('Kitoblar Katalogi'!E$3:E$52,22),"") -> 73878 | F24: =IFERROR(INDEX('Kitoblar Katalogi'!F$3:F$52,MATCH(LARGE('Kitoblar Katalogi'!E$3:E$52,22),'Kitoblar Katalogi'!E$3:E$52,0)),"") -> 38 | G24: =IFERROR(INDEX('Kitoblar Katalogi'!G$3:G$52,MATCH(LARGE('Kitoblar Katalogi'!E$3:E$52,22),'Kitoblar Katalogi'!E$3:E$52,0)),"") -> 2807364
A25: =IFERROR(INDEX('Kitoblar Katalogi'!A$3:A$52,MATCH(LARGE('Kitoblar Katalogi'!E$3:E$52,23),'Kitoblar Katalogi'!E$3:E$52,0)),"") -> 16 | B25: =IFERROR(INDEX('Kitoblar Katalogi'!B$3:B$52,MATCH(LARGE('Kitoblar Katalogi'!E$3:E$52,23),'Kitoblar Katalogi'!E$3:E$52,0)),"") -> Idiot | C25: =IFERROR(INDEX('Kitoblar Katalogi'!C$3:C$52,MATCH(LARGE('Kitoblar Katalogi'!E$3:E$52,23),'Kitoblar Katalogi'!E$3:E$52,0)),"") -> Dostoevskiy | D25: =IFERROR(INDEX('Kitoblar Katalogi'!D$3:D$52,MATCH(LARGE('Kitoblar Katalogi'!E$3:E$52,23),'Kitoblar Katalogi'!E$3:E$52,0)),"") -> Biografiya | E25: =IFERROR(LARGE('Kitoblar Katalogi'!E$3:E$52,23),"") -> 69987 | F25: =IFERROR(INDEX('Kitoblar Katalogi'!F$3:F$52,MATCH(LARGE('Kitoblar Katalogi'!E$3:E$52,23),'Kitoblar Katalogi'!E$3:E$52,0)),"") -> 15 | G25: =IFERROR(INDEX('Kitoblar Katalogi'!G$3:G$52,MATCH(LARGE('Kitoblar Katalogi'!E$3:E$52,23),'Kitoblar Katalogi'!E$3:E$52,0)),"") -> 1049805
A26: =IFERROR(INDEX('Kitoblar Katalogi'!A$3:A$52,MATCH(LARGE('Kitoblar Katalogi'!E$3:E$52,24),'Kitoblar Katalogi'!E$3:E$52,0)),"") -> 40 | B26: =IFERROR(INDEX('Kitoblar Katalogi'!B$3:B$52,MATCH(LARGE('Kitoblar Katalogi'!E$3:E$52,24),'Kitoblar Katalogi'!E$3:E$52,0)),"") -> Baxtsiz oshiq | C26: =IFERROR(INDEX('Kitoblar Katalogi'!C$3:C$52,MATCH(LARGE('Kitoblar Katalogi'!E$3:E$52,24),'Kitoblar Katalogi'!E$3:E$52,0)),"") -> Gyote | D26: =IFERROR(INDEX('Kitoblar Katalogi'!D$3:D$52,MATCH(LARGE('Kitoblar Katalogi'!E$3:E$52,24),'Kitoblar Katalogi'!E$3:E$52,0)),"") -> Roman | E26: =IFERROR(LARGE('Kitoblar Katalogi'!E$3:E$52,24),"") -> 64823 | F26: =IFERROR(INDEX('Kitoblar Katalogi'!F$3:F$52,MATCH(LARGE('Kitoblar Katalogi'!E$3:E$52,24),'Kitoblar Katalogi'!E$3:E$52,0)),"") -> 18 | G26: =IFERROR(INDEX('Kitoblar Katalogi'!G$3:G$52,MATCH(LARGE('Kitoblar Katalogi'!E$3:E$52,24),'Kitoblar Katalogi'!E$3:E$52,0)),"") -> 1166814
A27: =IFERROR(INDEX('Kitoblar Katalogi'!A$3:A$52,MATCH(LARGE('Kitoblar Katalogi'!E$3:E$52,25),'Kitoblar Katalogi'!E$3:E$52,0)),"") -> 25 | B27: =IFERROR(INDEX('Kitoblar Katalogi'!B$3:B$52,MATCH(LARGE('Kitoblar Katalogi'!E$3:E$52,25),'Kitoblar Katalogi'!E$3:E$52,0)),"") -> 1984 | C27: =IFERROR(INDEX('Kitoblar Katalogi'!C$3:C$52,MATCH(LARGE('Kitoblar Katalogi'!E$3:E$52,25),'Kitoblar Katalogi'!E$3:E$52,0)),"") -> Jorj Oruell | D27: =IFERROR(INDEX('Kitoblar Katalogi'!D$3:D$52,MATCH(LARGE('Kitoblar Katalogi'!E$3:E$52,25),'Kitoblar Katalogi'!E$3:E$52,0)),"") -> Falsafa | E27: =IFERROR(LARGE('Kitoblar Katalogi'!E$3:E$52,25),"") -> 64797 | F27: =IFERROR(INDEX('Kitoblar Katalogi'!F$3:F$52,MATCH(LARGE('Kitoblar Katalogi'!E$3:E$52,25),'Kitoblar Katalogi'!E$3:E$52,0)),"") -> 7 | G27: =IFERROR(INDEX('Kitoblar Katalogi'!G$3:G$52,MATCH(LARGE('Kitoblar Katalogi'!E$3:E$52,25),'Kitoblar Katalogi'!E$3:E$52,0)),"") -> 453579
A28: =IFERROR(INDEX('Kitoblar Katalogi'!A$3:A$52,MATCH(LARGE('Kitoblar Katalogi'!E$3:E$52,26),'Kitoblar Katalogi'!E$3:E$52,0)),"") -> 43 | B28: =IFERROR(INDEX('Kitoblar Katalogi'!B$3:B$52,MATCH(LARGE('Kitoblar Katalogi'!E$3:E$52,26),'Kitoblar Katalogi'!E$3:E$52,0)),"") -> Graf Monte-Kristo | C28: =IFERROR(INDEX('Kitoblar Katalogi'!C$3:C$52,MATCH(LARGE('Kitoblar Katalogi'!E$3:E$52,26),'Kitoblar Katalogi'!E$3:E$52,0)),"") -> Dyuma | D28: =IFERROR(INDEX('Kitoblar Katalogi'!D$3:D$52,MATCH(LARGE('Kitoblar Katalogi'!E$3:E$52,26),'Kitoblar Katalogi'!E$3:E$52,0)),"") -> Ilm-fan | E28: =IFERROR(LARGE('Kitoblar Katalogi'!E$3:E$52,26),"") -> 63520 | F28: =IFERROR(INDEX('Kitoblar Katalogi'!F$3:F$52,MATCH(LARGE('Kitoblar Katalogi'!E$3:E$52,26),'Kitoblar Katalogi'!E$3:E$52,0)),"") -> 23 | G28: =IFERROR(INDEX('Kitoblar Katalogi'!G$3:G$52,MATCH(LARGE('Kitoblar Katalogi'!E$3:E$52,26),'Kitoblar Katalogi'!E$3:E$52,0)),"") -> 1460960
A29: =IFERROR(INDEX('Kitoblar Katalogi'!A$3:A$52,MATCH(LARGE('Kitoblar Katalogi'!E$3:E$52,27),'Kitoblar Katalogi'!E$3:E$52,0)),"") -> 42 | B29: =IFERROR(INDEX('Kitoblar Katalogi'!B$3:B$52,MATCH(LARGE('Kitoblar Katalogi'!E$3:E$52,27),'Kitoblar Katalogi'!E$3:E$52,0)),"") -> Baxtsizlar | C29: =IFERROR(INDEX('Kitoblar Katalogi'!C$3:C$52,MATCH(LARGE('Kitoblar Katalogi'!E$3:E$52,27),'Kitoblar Katalogi'!E$3:E$52,0)),"") -> Gyugo | D29: =IFERROR(INDEX('Kitoblar Katalogi'!D$3:D$52,MATCH(LARGE('Kitoblar Katalogi'!E$3:E$52,27),'Kitoblar Katalogi'!E$3:E$52,0)),"") -> Tarix | E29: =IFERROR(LARGE('Kitoblar Katalogi'!E$3:E$52,27),"") -> 62819 | F29: =IFERROR(INDEX('Kitoblar Katalogi'!F$3:F$52,MATCH(LARGE('Kitoblar Katalogi'!E$3:E$52,27),'Kitoblar Katalogi'!E$3:E$52,0)),"") -> 11 | G29: =IFERROR(INDEX('Kitoblar Katalogi'!G$3:G$52,MATCH(LARGE('Kitoblar Katalogi'!E$3:E$52,27),'Kitoblar Katalogi'!E$3:E$52,0)),"") -> 691009
A30: =IFERROR(INDEX('Kitoblar Katalogi'!A$3:A$52,MATCH(LARGE('Kitoblar Katalogi'!E$3:E$52,28),'Kitoblar Katalogi'!E$3:E$52,0)),"") -> 26 | B30: =IFERROR(INDEX('Kitoblar Katalogi'!B$3:B$52,MATCH(LARGE('Kitoblar Katalogi'!E$3:E$52,28),'Kitoblar Katalogi'!E$3:E$52,0)),"") -> Hayvonlar fermasi | C30: =IFERROR(INDEX('Kitoblar Katalogi'!C$3:C$52,MATCH(LARGE('Kitoblar Katalogi'!E$3:E$52,28),'Kitoblar Katalogi'!E$3:E$52,0)),"") -> Jorj Oruell | D30: =IFERROR(INDEX('Kitoblar Katalogi'!D$3:D$52,MATCH(LARGE('Kitoblar Katalogi'!E$3:E$52,28),'Kitoblar Katalogi'!E$3:E$52,0)),"") -> Biografiya | E30: =IFERROR(LARGE('Kitoblar Katalogi'!E$3:E$52,28),"") -> 62052 | F30: =IFERROR(INDEX('Kitoblar Katalogi'!F$3:F$52,MATCH(LARGE('Kitoblar Katalogi'!E$3:E$52,28),'Kitoblar Katalogi'!E$3:E$52,0)),"") -> 23 | G30: =IFERROR(INDEX('Kitoblar Katalogi'!G$3:G$52,MATCH(LARGE('Kitoblar Katalogi'!E$3:E$52,28),'Kitoblar Katalogi'!E$3:E$52,0)),"") -> 1427196
A31: =IFERROR(INDEX('Kitoblar Katalogi'!A$3:A$52,MATCH(LARGE('Kitoblar Katalogi'!E$3:E$52,29),'Kitoblar Katalogi'!E$3:E$52,0)),"") -> 21 | B31: =IFERROR(INDEX('Kitoblar Katalogi'!B$3:B$52,MATCH(LARGE('Kitoblar Katalogi'!E$3:E$52,29),'Kitoblar Katalogi'!E$3:E$52,0)),"") -> Qor | C31: =IFERROR(INDEX('Kitoblar Katalogi'!C$3:C$52,MATCH(LARGE('Kitoblar Katalogi'!E$3:E$52,29),'Kitoblar Katalogi'!E$3:E$52,0)),"") -> Orhan Pamuk | D31: =IFERROR(INDEX('Kitoblar Katalogi'!D$3:D$52,MATCH(LARGE('Kitoblar Katalogi'!E$3:E$52,29),'Kitoblar Katalogi'!E$3:E$52,0)),"") -> Fantastika | E31: =IFERROR(LARGE('Kitoblar Katalogi'!E$3:E$52,29),"") -> 59597 | F31: =IFERROR(INDEX('Kitoblar Katalogi'!F$3:F$52,MATCH(LARGE('Kitoblar Katalogi'!E$3:E$52,29),'Kitoblar Katalogi'!E$3:E$52,0)),"") -> 18 | G31: =IFERROR(INDEX('Kitoblar Katalogi'!G$3:G$52,MATCH(LARGE('Kitoblar Katalogi'!E$3:E$52,29),'Kitoblar Katalogi'!E$3:E$52,0)),"") -> 1072746
A32: =IFERROR(INDEX('Kitoblar Katalogi'!A$3:A$52,MATCH(LARGE('Kitoblar Katalogi'!E$3:E$52,30),'Kitoblar Katalogi'!E$3:E$52,0)),"") -> 32 | B32: =IFERROR(INDEX('Kitoblar Katalogi'!B$3:B$52,MATCH(LARGE('Kitoblar Katalogi'!E$3:E$52,30),'Kitoblar Katalogi'!E$3:E$52,0)),"") -> Faust | C32: =IFERROR(INDEX('Kitoblar Katalogi'!C$3:C$52,MATCH(LARGE('Kitoblar Katalogi'!E$3:E$52,30),'Kitoblar Katalogi'!E$3:E$52,0)),"") -> Gyote | D32: =IFERROR(INDEX('Kitoblar Katalogi'!D$3:D$52,MATCH(LARGE('Kitoblar Katalogi'!E$3:E$52,30),'Kitoblar Katalogi'!E$3:E$52,0)),"") -> Tarix | E32: =IFERROR(LARGE('Kitoblar Katalogi'!E$3:E$52,30),"") -> 53427 | F32: =IFERROR(INDEX('Kitoblar Katalogi'!F$3:F$52,MATCH(LARGE('Kitoblar Katalogi'!E$3:E$52,30),'Kitoblar Katalogi'!E$3:E$52,0)),"") -> 41 | G32: =IFERROR(INDEX('Kitoblar Katalogi'!G$3:G$52,MATCH(LARGE('Kitoblar Katalogi'!E$3:E$52,30),'Kitoblar Katalogi'!E$3:E$52,0)),"") -> 2190507
A33: =IFERROR(INDEX('Kitoblar Katalogi'!A$3:A$52,MATCH(LARGE('Kitoblar Katalogi'!E$3:E$52,31),'Kitoblar Katalogi'!E$3:E$52,0)),"") -> 38 | B33: =IFERROR(INDEX('Kitoblar Katalogi'!B$3:B$52,MATCH(LARGE('Kitoblar Katalogi'!E$3:E$52,31),'Kitoblar Katalogi'!E$3:E$52,0)),"") -> Robinzon Kruzo | C33: =IFERROR(INDEX('Kitoblar Katalogi'!C$3:C$52,MATCH(LARGE('Kitoblar Katalogi'!E$3:E$52,31),'Kitoblar Katalogi'!E$3:E$52,0)),"") -> Defo | D33: =IFERROR(INDEX('Kitoblar Katalogi'!D$3:D$52,MATCH(LARGE('Kitoblar Katalogi'!E$3:E$52,31),'Kitoblar Katalogi'!E$3:E$52,0)),"") -> Psixologiya | E33: =IFERROR(LARGE('Kitoblar Katalogi'!E$3:E$52,31),"") -> 52930 | F33: =IFERROR(INDEX('Kitoblar Katalogi'!F$3:F$52,MATCH(LARGE('Kitoblar Katalogi'!E$3:E$52,31),'Kitoblar Katalogi'!E$3:E$52,0)),"") -> 6 | G33: =IFERROR(INDEX('Kitoblar Katalogi'!G$3:G$52,MATCH(LARGE('Kitoblar Katalogi'!E$3:E$52,31),'Kitoblar Katalogi'!E$3:E$52,0)),"") -> 317580
A34: =IFERROR(INDEX('Kitoblar Katalogi'!A$3:A$52,MATCH(LARGE('Kitoblar Katalogi'!E$3:E$52,32),'Kitoblar Katalogi'!E$3:E$52,0)),"") -> 18 | B34: =IFERROR(INDEX('Kitoblar Katalogi'!B$3:B$52,MATCH(LARGE('Kitoblar Katalogi'!E$3:E$52,32),'Kitoblar Katalogi'!E$3:E$52,0)),"") -> 100 yillik yolg'izlik | C34: =IFERROR(INDEX('Kitoblar Katalogi'!C$3:C$52,MATCH(LARGE('Kitoblar Katalogi'!E$3:E$52,32),'Kitoblar Katalogi'!E$3:E$52,0)),"") -> Markes | D34: =IFERROR(INDEX('Kitoblar Katalogi'!D$3:D$52,MATCH(LARGE('Kitoblar Katalogi'!E$3:E$52,32),'Kitoblar Katalogi'!E$3:E$52,0)),"") -> Psixologiya | E34: =IFERROR(LARGE('Kitoblar Katalogi'!E$3:E$52,32),"") -> 51463 | F34: =IFERROR(INDEX('Kitoblar Katalogi'!F$3:F$52,MATCH(LARGE('Kitoblar Katalogi'!E$3:E$52,32),'Kitoblar Katalogi'!E$3:E$52,0)),"") -> 1 | G34: =IFERROR(INDEX('Kitoblar Katalogi'!G$3:G$52,MATCH(LARGE('Kitoblar Katalogi'!E$3:E$52,32),'Kitoblar Katalogi'!E$3:E$52,0)),"") -> 51463
A35: =IFERROR(INDEX('Kitoblar Katalogi'!A$3:A$52,MATCH(LARGE('Kitoblar Katalogi'!E$3:E$52,33),'Kitoblar Katalogi'!E$3:E$52,0)),"") -> 3 | B35: =IFERROR(INDEX('Kitoblar Katalogi'!B$3:B$52,MATCH(LARGE('Kitoblar Katalogi'!E$3:E$52,33),'Kitoblar Katalogi'!E$3:E$52,0)),"") -> Sarob | C35: =IFERROR(INDEX('Kitoblar Katalogi'!C$3:C$52,MATCH(LARGE('Kitoblar Katalogi'!E$3:E$52,33),'Kitoblar Katalogi'!E$3:E$52,0)),"") -> Abdulla Qahhor | D35: =IFERROR(INDEX('Kitoblar Katalogi'!D$3:D$52,MATCH(LARGE('Kitoblar Katalogi'!E$3:E$52,33),'Kitoblar Katalogi'!E$3:E$52,0)),"") -> Ilm-fan | E35: =IFERROR(LARGE('Kitoblar Katalogi'!E$3:E$52,33),"") -> 51048 | F35: =IFERROR(INDEX('Kitoblar Katalogi'!F$3:F$52,MATCH(LARGE('Kitoblar Katalogi'!E$3:E$52,33),'Kitoblar Katalogi'!E$3:E$52,0)),"") -> 16 | G35: =IFERROR(INDEX('Kitoblar Katalogi'!G$3:G$52,MATCH(LARGE('Kitoblar Katalogi'!E$3:E$52,33),'Kitoblar Katalogi'!E$3:E$52,0)),"") -> 816768
A36: =IFERROR(INDEX('Kitoblar Katalogi'!A$3:A$52,MATCH(LARGE('Kitoblar Katalogi'!E$3:E$52,34),'Kitoblar Katalogi'!E$3:E$52,0)),"") -> 45 | B36: =IFERROR(INDEX('Kitoblar Katalogi'!B$3:B$52,MATCH(LARGE('Kitoblar Katalogi'!E$3:E$52,34),'Kitoblar Katalogi'!E$3:E$52,0)),"") -> Piter Pan | C36: =IFERROR(INDEX('Kitoblar Katalogi'!C$3:C$52,MATCH(LARGE('Kitoblar Katalogi'!E$3:E$52,34),'Kitoblar Katalogi'!E$3:E$52,0)),"") -> Barri | D36: =IFERROR(INDEX('Kitoblar Katalogi'!D$3:D$52,MATCH(LARGE('Kitoblar Katalogi'!E$3:E$52,34),'Kitoblar Katalogi'!E$3:E$52,0)),"") -> Falsafa | E36: =IFERROR(LARGE('Kitoblar Katalogi'!E$3:E$52,34),"") -> 49993 | F36: =IFERROR(INDEX('Kitoblar Katalogi'!F$3:F$52,MATCH(LARGE('Kitoblar Katalogi'!E$3:E$52,34),'Kitoblar Katalogi'!E$3:E$52,0)),"") -> 45 | G36: =IFERROR(INDEX('Kitoblar Katalogi'!G$3:G$52,MATCH(LARGE('Kitoblar Katalogi'!E$3:E$52,34),'Kitoblar Katalogi'!E$3:E$52,0)),"") -> 2249685
A37: =IFERROR(INDEX('Kitoblar Katalogi'!A$3:A$52,MATCH(LARGE('Kitoblar Katalogi'!E$3:E$52,35),'Kitoblar Katalogi'!E$3:E$52,0)),"") -> 50 | B37: =IFERROR(INDEX('Kitoblar Katalogi'!B$3:B$52,MATCH(LARGE('Kitoblar Katalogi'!E$3:E$52,35),'Kitoblar Katalogi'!E$3:E$52,0)),"") -> Ko'hna dunyo | C37: =IFERROR(INDEX('Kitoblar Katalogi'!C$3:C$52,MATCH(LARGE('Kitoblar Katalogi'!E$3:E$52,35),'Kitoblar Katalogi'!E$3:E$52,0)),"") -> Tog'ay Murod | D37: =IFERROR(INDEX('Kitoblar Katalogi'!D$3:D$52,MATCH(LARGE('Kitoblar Katalogi'!E$3:E$52,35),'Kitoblar Katalogi'!E$3:E$52,0)),"") -> Roman | E37: =IFERROR(LARGE('Kitoblar Katalogi'!E$3:E$52,35),"") -> 47087 | F37: =IFERROR(INDEX('Kitoblar Katalogi'!F$3:F$52,MATCH(LARGE('Kitoblar Katalogi'!E$3:E$52,35),'Kitoblar Katalogi'!E$3:E$52,0)),"") -> 11 | G37: =IFERROR(INDEX('Kitoblar Katalogi'!G$3:G$52,MATCH(LARGE('Kitoblar Katalogi'!E$3:E$52,35),'Kitoblar Katalogi'!E$3:E$52,0)),"") -> 517957
A38: =IFERROR(INDEX('Kitoblar Katalogi'!A$3:A$52,MATCH(LARGE('Kitoblar Katalogi'!E$3:E$52,36),'Kitoblar Katalogi'!E$3:E$52,0)),"") -> 39 | B38: =IFERROR(INDEX('Kitoblar Katalogi'!B$3:B$52,MATCH(LARGE('Kitoblar Katalogi'!E$3:E$52,36),'Kitoblar Katalogi'!E$3:E$52,0)),"") -> Mobi Dik | C38: =IFERROR(INDEX('Kitoblar Katalogi'!C$3:C$52,MATCH(LARGE('Kitoblar Katalogi'!E$3:E$52,36),'Kitoblar Katalogi'!E$3:E$52,0)),"") -> Melvill | D38: =IFERROR(INDEX('Kitoblar Katalogi'!D$3:D$52,MATCH(LARGE('Kitoblar Katalogi'!E$3:E$52,36),'Kitoblar Katalogi'!E$3:E$52,0)),"") -> Bolalar | E38: =IFERROR(LARGE('Kitoblar Katalogi'!E$3:E$52,36),"") -> 45512 | F38: =IFERROR(INDEX('Kitoblar Katalogi'!F$3:F$52,MATCH(LARGE('Kitoblar Katalogi'!E$3:E$52,36),'Kitoblar Katalogi'!E$3:E$52,0)),"") -> 7 | G38: =IFERROR(INDEX('Kitoblar Katalogi'!G$3:G$52,MATCH(LARGE('Kitoblar Katalogi'!E$3:E$52,36),'Kitoblar Katalogi'!E$3:E$52,0)),"") -> 318584
A39: =IFERROR(INDEX('Kitoblar Katalogi'!A$3:A$52,MATCH(LARGE('Kitoblar Katalogi'!E$3:E$52,37),'Kitoblar Katalogi'!E$3:E$52,0)),"") -> 11 | B39: =IFERROR(INDEX('Kitoblar Katalogi'!B$3:B$52,MATCH(LARGE('Kitoblar Katalogi'!E$3:E$52,37),'Kitoblar Katalogi'!E$3:E$52,0)),"") -> Don Kixot | C39: =IFERROR(INDEX('Kitoblar Katalogi'!C$3:C$52,MATCH(LARGE('Kitoblar Katalogi'!E$3:E$52,37),'Kitoblar Katalogi'!E$3:E$52,0)),"") -> Servantes | D39: =IFERROR(INDEX('Kitoblar Katalogi'!D$3:D$52,MATCH(LARGE('Kitoblar Katalogi'!E$3:E$52,37),'Kitoblar Katalogi'!E$3:E$52,0)),"") -> Fantastika | E39: =IFERROR(LARGE('Kitoblar Katalogi'!E$3:E$52,37),"") -> 45495 | F39: =IFERROR(INDEX('Kitoblar Katalogi'!F$3:F$52,MATCH(LARGE('Kitoblar Katalogi'!E$3:E$52,37),'Kitoblar Katalogi'!E$3:E$52,0)),"") -> 33 | G39: =IFERROR(INDEX('Kitoblar Katalogi'!G$3:G$52,MATCH(LARGE('Kitoblar Katalogi'!E$3:E$52,37),'Kitoblar Katalogi'!E$3:E$52,0)),"") -> 1501335
A40: =IFERROR(INDEX('Kitoblar Katalogi'!A$3:A$52,MATCH(LARGE('Kitoblar Katalogi'!E$3:E$52,38),'Kitoblar Katalogi'!E$3:E$52,0)),"") -> 37 | B40: =IFERROR(INDEX('Kitoblar Katalogi'!B$3:B$52,MATCH(LARGE('Kitoblar Katalogi'!E$3:E$52,38),'Kitoblar Katalogi'!E$3:E$52,0)),"") -> Kichkina knyaz | C40: =IFERROR(INDEX('Kitoblar Katalogi'!C$3:C$52,MATCH(LARGE('Kitoblar Katalogi'!E$3:E$52,38),'Kitoblar Katalogi'!E$3:E$52,0)),"") -> Sent-Ekzyuperi | D40: =IFERROR(INDEX('Kitoblar Katalogi'!D$3:D$52,MATCH(LARGE('Kitoblar Katalogi'!E$3:E$52,38),'Kitoblar Katalogi'!E$3:E$52,0)),"") -> Detektiv | E40: =IFERROR(LARGE('Kitoblar Katalogi'!E$3:E$52,38),"") -> 44871 | F40: =IFERROR(INDEX('Kitoblar Katalogi'!F$3:F$52,MATCH(LARGE('Kitoblar Katalogi'!E$3:E$52,38),'Kitoblar Katalogi'!E$3:E$52,0)),"") -> 50 | G40: =IFERROR(INDEX('Kitoblar Katalogi'!G$3:G$52,MATCH(LARGE('Kitoblar Katalogi'!E$3:E$52,38),'Kitoblar Katalogi'!E$3:E$52,0)),"") -> 2243550
...
